<?xml version="1.0" ?>
<!-- =================================================================================== -->
<!-- |    This document was autogenerated by xacro from premaidai.urdf.xacro           | -->
<!-- |    EDITING THIS FILE BY HAND IS NOT RECOMMENDED                                 | -->
<!-- =================================================================================== -->
<robot name="premaidai" xmlns:xacro="http://ros.org/wiki/xacro">
  <link name="base_link">
    <inertial>
      <mass value="0.001"/>
      <inertia ixx="0." ixy="0." ixz="0." iyy="0." iyz="0." izz="0."/>
    </inertial>
  </link>
  <link name="r_hip_joint">
    <visual>
      <origin rpy="0 0 0" xyz="0 0 0"/>
      <geometry>
        <mesh filename="package://assets/meshes/r_hip_joint.dae"/>
      </geometry>
    </visual>
    <collision>
      <origin rpy="0 0 0" xyz="0 0 0"/>
      <geometry>
        <mesh filename="package://assets/meshes/r_hip_joint.dae"/>
      </geometry>
    </collision>
    <inertial>
      <mass value="0.0143"/>
      <origin xyz="0.000000 -0.000183 -0.010532"/>
      <inertia ixx="20.138887e-10" ixy="-0.000001e-10" ixz="0.0e-10" iyy="53.757824e-10" iyz="5.18773e-11" izz="46.127151e-10"/>
    </inertial>
  </link>
  <link name="r_uleg_root">
    <visual>
      <origin rpy="0 0 0" xyz="0 0 0"/>
      <geometry>
        <mesh filename="package://assets/meshes/r_uleg_root.dae"/>
      </geometry>
    </visual>
    <collision>
      <origin rpy="0 0 0" xyz="0 0 0"/>
      <geometry>
        <mesh filename="package://assets/meshes/r_uleg_root.dae"/>
      </geometry>
    </collision>
    <inertial>
      <mass value="0.0648"/>
      <origin xyz="-0.000000 -0.01342 -0.004373"/>
      <inertia ixx="246.003845e-10" ixy="1.517e-13" ixz="-0.001688e-10" iyy="191.922195e-10" iyz="6.165664e-10" izz="238.454895e-10"/>
    </inertial>
  </link>
  <link name="r_uleg">
    <visual>
      <origin rpy="0 0 0" xyz="0 0 0"/>
      <geometry>
        <mesh filename="package://assets/meshes/r_uleg.dae"/>
      </geometry>
    </visual>
    <collision>
      <origin rpy="0 0 0" xyz="0 0 0"/>
      <geometry>
        <mesh filename="package://assets/meshes/r_uleg.dae"/>
      </geometry>
    </collision>
    <inertial>
      <mass value="0.1134"/>
      <origin xyz="-0.000000 0.000001 -0.032601"/>
      <inertia ixx="884.390869e-10" ixy="0.000002e-10" ixz="-0.000046e-10" iyy="825.489990e-10" iyz="-0.000031e-10" izz="222.801773e-10"/>
    </inertial>
  </link>
  <link name="r_lleg">
    <visual>
      <origin rpy="0 0 0" xyz="0 0 0"/>
      <geometry>
        <mesh filename="package://assets/meshes/r_lleg.dae"/>
      </geometry>
    </visual>
    <collision>
      <origin rpy="0 0 0" xyz="0 0 0"/>
      <geometry>
        <mesh filename="package://assets/meshes/r_lleg.dae"/>
      </geometry>
    </collision>
    <inertial>
      <mass value="0.0719"/>
      <origin xyz="-0.001624 -0.002494 -0.034776"/>
      <inertia ixx="735.568420e-10" ixy="1.871153e-10" ixz="-35.647034e-10" iyy="434.662354e-10" iyz="-2.47592e-11" izz="480.555054e-10"/>
    </inertial>
  </link>
  <link name="r_ankle">
    <visual>
      <origin rpy="0 0 0" xyz="0 0 0"/>
      <geometry>
        <mesh filename="package://assets/meshes/r_ankle.dae"/>
      </geometry>
    </visual>
    <collision>
      <origin rpy="0 0 0" xyz="0 0 0"/>
      <geometry>
        <mesh filename="package://assets/meshes/r_ankle.dae"/>
      </geometry>
    </collision>
    <inertial>
      <mass value="0.0571"/>
      <origin xyz="-0.009629 0.000379 -0.003702"/>
      <inertia ixx="175.244446e-10" ixy="-0.000004e-10" ixz="11.289989e-10" iyy="257.425598e-10" iyz="-0.000002e-10" izz="224.547821e-10"/>
    </inertial>
  </link>
  <link name="r_foot">
    <visual>
      <origin rpy="0 0 0" xyz="0 0 0"/>
      <geometry>
        <mesh filename="package://assets/meshes/r_foot.dae"/>
      </geometry>
    </visual>
    <collision>
      <origin rpy="0 0 0" xyz="0 0 0"/>
      <geometry>
        <mesh filename="package://assets/meshes/r_foot.dae"/>
      </geometry>
    </collision>
    <inertial>
      <mass value="0.0941"/>
      <origin xyz="0.005014 -0.008793 -0.004123"/>
      <inertia ixx="383.406982e-10" ixy="-1.1222215e-09" ixz="12.157411e-10" iyy="1013.430359e-10" iyz="1.649494e-10" izz="1206.411377e-10"/>
    </inertial>
  </link>
  <joint name="r_hpz_joint" type="revolute">
    <origin rpy="0 0 0" xyz="0.004225 -0.0195245 0.001412"/>
    <axis xyz="0 0 1"/>
    <limit effort="0" lower="-1.41371669412" upper="1.78774075282" velocity="428.6"/>
    <parent link="base_link"/>
    <child link="r_hip_joint"/>
  </joint>
  <joint name="r_hpx_joint" type="revolute">
    <origin rpy="0 0 0" xyz="0 0.0021 -0.028"/>
    <axis xyz="1 0 0"/>
    <limit effort="0" lower="-0.442440965381" upper="0.396416633005" velocity="428.6"/>
    <parent link="r_hip_joint"/>
    <child link="r_uleg_root"/>
  </joint>
  <joint name="r_hpy_joint" type="revolute">
    <origin rpy="0 0 0" xyz="0 -0.0128525 -0.034358"/>
    <axis xyz="0 1 0"/>
    <limit effort="0" lower="-1.59872159483" upper="1.5745138781" velocity="428.6"/>
    <parent link="r_uleg_root"/>
    <child link="r_uleg"/>
  </joint>
  <joint name="r_kny_joint" type="revolute">
    <origin rpy="0 0 0" xyz="0 0 -0.0652"/>
    <axis xyz="0 1 0"/>
    <limit effort="0" lower="-0.036521014598" upper="2.08811191709" velocity="428.6"/>
    <parent link="r_uleg"/>
    <child link="r_lleg"/>
  </joint>
  <joint name="r_aky_joint" type="revolute">
    <origin rpy="0 0 0" xyz="0 0 -0.065"/>
    <axis xyz="0 1 0"/>
    <limit effort="0" lower="-1.07089039579" upper="0.424115008235" velocity="428.6"/>
    <parent link="r_lleg"/>
    <child link="r_ankle"/>
  </joint>
  <joint name="r_akx_joint" type="revolute">
    <origin rpy="0 0 0" xyz="0 0 -0.040677"/>
    <axis xyz="1 0 0"/>
    <limit effort="0" lower="-0.667392089347" upper="0.650898727916" velocity="428.6"/>
    <parent link="r_ankle"/>
    <child link="r_foot"/>
  </joint>
  <gazebo reference="r_hip_joint">
    <selfCollide>false</selfCollide>
  </gazebo>
  <gazebo reference="r_uleg_root">
    <selfCollide>false</selfCollide>
  </gazebo>
  <gazebo reference="r_uleg">
    <selfCollide>false</selfCollide>
  </gazebo>
  <gazebo reference="r_lleg">
    <selfCollide>false</selfCollide>
  </gazebo>
  <gazebo reference="r_ankle">
    <selfCollide>false</selfCollide>
  </gazebo>
  <gazebo reference="r_foot">
    <selfCollide>false</selfCollide>
  </gazebo>
  <link name="l_hip_joint">
    <visual>
      <origin rpy="0 0 0" xyz="0 0 0"/>
      <geometry>
        <mesh filename="package://assets/meshes/l_hip_joint.dae"/>
      </geometry>
    </visual>
    <collision>
      <origin rpy="0 0 0" xyz="0 0 0"/>
      <geometry>
        <mesh filename="package://assets/meshes/l_hip_joint.dae"/>
      </geometry>
    </collision>
    <inertial>
      <mass value="0.0143"/>
      <origin xyz="0.000000 0.000183 -0.010532"/>
      <inertia ixx="20.138887e-10" ixy="-0.000001e-10" ixz="0.0e-10" iyy="53.757824e-10" iyz="-5.18773e-11" izz="46.127151e-10"/>
    </inertial>
  </link>
  <link name="l_uleg_root">
    <visual>
      <origin rpy="0 0 0" xyz="0 0 0"/>
      <geometry>
        <mesh filename="package://assets/meshes/l_uleg_root.dae"/>
      </geometry>
    </visual>
    <collision>
      <origin rpy="0 0 0" xyz="0 0 0"/>
      <geometry>
        <mesh filename="package://assets/meshes/l_uleg_root.dae"/>
      </geometry>
    </collision>
    <inertial>
      <mass value="0.0648"/>
      <origin xyz="-0.000000 0.01342 -0.004373"/>
      <inertia ixx="246.003845e-10" ixy="-1.517e-13" ixz="-0.001688e-10" iyy="191.922195e-10" iyz="-6.165664e-10" izz="238.454895e-10"/>
    </inertial>
  </link>
  <link name="l_uleg">
    <visual>
      <origin rpy="0 0 0" xyz="0 0 0"/>
      <geometry>
        <mesh filename="package://assets/meshes/l_uleg.dae"/>
      </geometry>
    </visual>
    <collision>
      <origin rpy="0 0 0" xyz="0 0 0"/>
      <geometry>
        <mesh filename="package://assets/meshes/l_uleg.dae"/>
      </geometry>
    </collision>
    <inertial>
      <mass value="0.1134"/>
      <origin xyz="-0.000000 0.000001 -0.032601"/>
      <inertia ixx="884.390869e-10" ixy="0.000002e-10" ixz="-0.000046e-10" iyy="825.489990e-10" iyz="-0.000031e-10" izz="222.801773e-10"/>
    </inertial>
  </link>
  <link name="l_lleg">
    <visual>
      <origin rpy="0 0 0" xyz="0 0 0"/>
      <geometry>
        <mesh filename="package://assets/meshes/l_lleg.dae"/>
      </geometry>
    </visual>
    <collision>
      <origin rpy="0 0 0" xyz="0 0 0"/>
      <geometry>
        <mesh filename="package://assets/meshes/l_lleg.dae"/>
      </geometry>
    </collision>
    <inertial>
      <mass value="0.0719"/>
      <origin xyz="-0.001624 0.002494 -0.034776"/>
      <inertia ixx="735.568420e-10" ixy="-1.871153e-10" ixz="-35.647034e-10" iyy="434.662354e-10" iyz="2.47592e-11" izz="480.555054e-10"/>
    </inertial>
  </link>
  <link name="l_ankle">
    <visual>
      <origin rpy="0 0 0" xyz="0 0 0"/>
      <geometry>
        <mesh filename="package://assets/meshes/l_ankle.dae"/>
      </geometry>
    </visual>
    <collision>
      <origin rpy="0 0 0" xyz="0 0 0"/>
      <geometry>
        <mesh filename="package://assets/meshes/l_ankle.dae"/>
      </geometry>
    </collision>
    <inertial>
      <mass value="0.0571"/>
      <origin xyz="-0.009629 0.000379 -0.003702"/>
      <inertia ixx="175.244446e-10" ixy="-0.000004e-10" ixz="11.289989e-10" iyy="257.425598e-10" iyz="-0.000002e-10" izz="224.547821e-10"/>
    </inertial>
  </link>
  <link name="l_foot">
    <visual>
      <origin rpy="0 0 0" xyz="0 0 0"/>
      <geometry>
        <mesh filename="package://assets/meshes/l_foot.dae"/>
      </geometry>
    </visual>
    <collision>
      <origin rpy="0 0 0" xyz="0 0 0"/>
      <geometry>
        <mesh filename="package://assets/meshes/l_foot.dae"/>
      </geometry>
    </collision>
    <inertial>
      <mass value="0.0941"/>
      <origin xyz="0.005014 0.008793 -0.004123"/>
      <inertia ixx="383.406982e-10" ixy="1.1222215e-09" ixz="12.157411e-10" iyy="1013.430359e-10" iyz="-1.649494e-10" izz="1206.411377e-10"/>
    </inertial>
  </link>
  <joint name="l_hpz_joint" type="revolute">
    <origin rpy="0 0 0" xyz="0.004225 0.0195245 0.001412"/>
    <axis xyz="0 0 1"/>
    <limit effort="0" lower="-1.41371669412" upper="1.78774075282" velocity="428.6"/>
    <parent link="base_link"/>
    <child link="l_hip_joint"/>
  </joint>
  <joint name="l_hpx_joint" type="revolute">
    <origin rpy="0 0 0" xyz="0 -0.0021 -0.028"/>
    <axis xyz="1 0 0"/>
    <limit effort="0" lower="-0.396416633005" upper="0.442440965381" velocity="428.6"/>
    <parent link="l_hip_joint"/>
    <child link="l_uleg_root"/>
  </joint>
  <joint name="l_hpy_joint" type="revolute">
    <origin rpy="0 0 0" xyz="0 0.0128525 -0.034358"/>
    <axis xyz="0 1 0"/>
    <limit effort="0" lower="-1.59872159483" upper="1.5745138781" velocity="428.6"/>
    <parent link="l_uleg_root"/>
    <child link="l_uleg"/>
  </joint>
  <joint name="l_kny_joint" type="revolute">
    <origin rpy="0 0 0" xyz="0 0 -0.0652"/>
    <axis xyz="0 1 0"/>
    <limit effort="0" lower="-0.036521014598" upper="2.08811191709" velocity="428.6"/>
    <parent link="l_uleg"/>
    <child link="l_lleg"/>
  </joint>
  <joint name="l_aky_joint" type="revolute">
    <origin rpy="0 0 0" xyz="0 0 -0.065"/>
    <axis xyz="0 1 0"/>
    <limit effort="0" lower="-1.07089039579" upper="0.424115008235" velocity="428.6"/>
    <parent link="l_lleg"/>
    <child link="l_ankle"/>
  </joint>
  <joint name="l_akx_joint" type="revolute">
    <origin rpy="0 0 0" xyz="0 0 -0.040677"/>
    <axis xyz="1 0 0"/>
    <limit effort="0" lower="-0.650898727916" upper="0.667392089347" velocity="428.6"/>
    <parent link="l_ankle"/>
    <child link="l_foot"/>
  </joint>
  <gazebo reference="l_hip_joint">
    <selfCollide>false</selfCollide>
  </gazebo>
  <gazebo reference="l_uleg_root">
    <selfCollide>false</selfCollide>
  </gazebo>
  <gazebo reference="l_uleg">
    <selfCollide>false</selfCollide>
  </gazebo>
  <gazebo reference="l_lleg">
    <selfCollide>false</selfCollide>
  </gazebo>
  <gazebo reference="l_ankle">
    <selfCollide>false</selfCollide>
  </gazebo>
  <gazebo reference="l_foot">
    <selfCollide>false</selfCollide>
  </gazebo>
  <link name="r_uarm_joint">
    <visual>
      <origin rpy="0 0 0" xyz="0 0 0"/>
      <geometry>
        <mesh filename="package://assets/meshes/r_uarm_joint.dae"/>
      </geometry>
    </visual>
    <collision>
      <origin rpy="0 0 0" xyz="0 0 0"/>
      <geometry>
        <mesh filename="package://assets/meshes/r_uarm_joint.dae"/>
      </geometry>
    </collision>
    <inertial>
      <mass value="0.0131"/>
      <origin xyz="-0.000000 -0.005109 0.000865"/>
      <inertia ixx="39.090332e-10" ixy="0.000021e-10" ixz="0.000003e-10" iyy="116.438423e-10" iyz="4.044059e-10" izz="132.243393e-10"/>
    </inertial>
  </link>
  <link name="r_uarm">
    <visual>
      <origin rpy="0 0 0" xyz="0 0 0"/>
      <geometry>
        <mesh filename="package://assets/meshes/r_uarm.dae"/>
      </geometry>
    </visual>
    <collision>
      <origin rpy="0 0 0" xyz="0 0 0"/>
      <geometry>
        <mesh filename="package://assets/meshes/r_uarm.dae"/>
      </geometry>
    </collision>
    <inertial>
      <mass value="0.0712"/>
      <origin xyz="-0.000001 -0.02164 0.000670"/>
      <inertia ixx="356.620514e-10" ixy="-0.000020e-10" ixz="0.000026e-10" iyy="126.890160e-10" iyz="-4.816492e-10" izz="414.000244e-10"/>
    </inertial>
  </link>
  <link name="r_larm_joint">
    <visual>
      <origin rpy="0 0 0" xyz="0 0 0"/>
      <geometry>
        <mesh filename="package://assets/meshes/r_larm_joint.dae"/>
      </geometry>
    </visual>
    <collision>
      <origin rpy="0 0 0" xyz="0 0 0"/>
      <geometry>
        <mesh filename="package://assets/meshes/r_larm_joint.dae"/>
      </geometry>
    </collision>
    <inertial>
      <mass value="0.0124"/>
      <origin xyz="-0.008596 -0.015762 0.002150"/>
      <inertia ixx="70.485497e-10" ixy="-1.04342163e-08" ixz="-0.000005e-10" iyy="188.648819e-10" iyz="3.8465e-10" izz="236.494141e-10"/>
    </inertial>
  </link>
  <link name="r_larm">
    <visual>
      <origin rpy="0 0 0" xyz="0 0 0"/>
      <geometry>
        <mesh filename="package://assets/meshes/r_larm.dae"/>
      </geometry>
    </visual>
    <collision>
      <origin rpy="0 0 0" xyz="0 0 0"/>
      <geometry>
        <mesh filename="package://assets/meshes/r_larm.dae"/>
      </geometry>
    </collision>
    <inertial>
      <mass value="0.0812"/>
      <origin xyz="-0.008596 -0.027572 0.000420"/>
      <inertia ixx="342.361237e-10" ixy="3.6e-15" ixz="0.000012e-10" iyy="141.587677e-10" iyz="-3.82193e-11" izz="414.116486e-10"/>
    </inertial>
  </link>
  <link name="r_hand">
    <visual>
      <origin rpy="0 0 0" xyz="0 0 0"/>
      <geometry>
        <mesh filename="package://assets/meshes/r_hand.dae"/>
      </geometry>
    </visual>
    <collision>
      <origin rpy="0 0 0" xyz="0 0 0"/>
      <geometry>
        <mesh filename="package://assets/meshes/r_hand.dae"/>
      </geometry>
    </collision>
    <inertial>
      <mass value="0.0046"/>
      <origin xyz="0.001817 -0.018911 0.002717"/>
      <inertia ixx="8.193970e-10" ixy="1.78483e-11" ixz="0.194812e-10" iyy="3.111708e-10" iyz="2.003531e-10" izz="9.081884e-10"/>
    </inertial>
  </link>
  <joint name="r_shy_joint" type="revolute">
    <origin rpy="0 0 0" xyz="0 -0.0359 0.113043"/>
    <axis xyz="0 1 0"/>
    <limit effort="0" lower="-1.88495559215" upper="2.23838476568" velocity="428.6"/>
    <parent link="base_link"/>
    <child link="r_uarm_joint"/>
  </joint>
  <joint name="r_shx_joint" type="revolute">
    <origin rpy="0 0 0" xyz="0 -0.0189 0"/>
    <axis xyz="1 0 0"/>
    <limit effort="0" lower="-0.0530143760293" upper="1.59808891297" velocity="428.6"/>
    <parent link="r_uarm_joint"/>
    <child link="r_uarm"/>
  </joint>
  <joint name="r_ely_joint" type="revolute">
    <origin rpy="0 0 0" xyz="0.0088013 -0.060007 0"/>
    <axis xyz="0 1 0"/>
    <limit effort="0" lower="-2.24604239778" upper="2.34441351774" velocity="428.6"/>
    <parent link="r_uarm"/>
    <child link="r_larm_joint"/>
  </joint>
  <joint name="r_elx_joint" type="revolute">
    <origin rpy="0 0 0" xyz="0 -0.024054 0"/>
    <axis xyz="1 0 0"/>
    <limit effort="0" lower="-0.235619449019" upper="2.07639639448" velocity="428.6"/>
    <parent link="r_larm_joint"/>
    <child link="r_larm"/>
  </joint>
  <joint name="r_wry_joint" type="revolute">
    <origin rpy="0 0 0" xyz="0 -0.061348 0"/>
    <axis xyz="0 1 0"/>
    <limit effort="0" lower="-2.35619449019" upper="2.06167017892" velocity="428.6"/>
    <parent link="r_larm"/>
    <child link="r_hand"/>
  </joint>
  <gazebo reference="r_uarm_joint">
    <selfCollide>true</selfCollide>
  </gazebo>
  <gazebo reference="r_uarm">
    <selfCollide>true</selfCollide>
  </gazebo>
  <gazebo reference="r_larm_joint">
    <selfCollide>true</selfCollide>
  </gazebo>
  <gazebo reference="r_larm">
    <selfCollide>true</selfCollide>
  </gazebo>
  <gazebo reference="r_hand">
    <selfCollide>true</selfCollide>
  </gazebo>
  <link name="l_uarm_joint">
    <visual>
      <origin rpy="0 0 0" xyz="0 0 0"/>
      <geometry>
        <mesh filename="package://assets/meshes/l_uarm_joint.dae"/>
      </geometry>
    </visual>
    <collision>
      <origin rpy="0 0 0" xyz="0 0 0"/>
      <geometry>
        <mesh filename="package://assets/meshes/l_uarm_joint.dae"/>
      </geometry>
    </collision>
    <inertial>
      <mass value="0.0131"/>
      <origin xyz="-0.000000 0.005109 0.000865"/>
      <inertia ixx="39.090332e-10" ixy="0.000021e-10" ixz="0.000003e-10" iyy="116.438423e-10" iyz="-4.044059e-10" izz="132.243393e-10"/>
    </inertial>
  </link>
  <link name="l_uarm">
    <visual>
      <origin rpy="0 0 0" xyz="0 0 0"/>
      <geometry>
        <mesh filename="package://assets/meshes/l_uarm.dae"/>
      </geometry>
    </visual>
    <collision>
      <origin rpy="0 0 0" xyz="0 0 0"/>
      <geometry>
        <mesh filename="package://assets/meshes/l_uarm.dae"/>
      </geometry>
    </collision>
    <inertial>
      <mass value="0.0712"/>
      <origin xyz="-0.000001 0.02164 0.000670"/>
      <inertia ixx="356.620514e-10" ixy="-0.000020e-10" ixz="0.000026e-10" iyy="126.890160e-10" iyz="4.816492e-10" izz="414.000244e-10"/>
    </inertial>
  </link>
  <link name="l_larm_joint">
    <visual>
      <origin rpy="0 0 0" xyz="0 0 0"/>
      <geometry>
        <mesh filename="package://assets/meshes/l_larm_joint.dae"/>
      </geometry>
    </visual>
    <collision>
      <origin rpy="0 0 0" xyz="0 0 0"/>
      <geometry>
        <mesh filename="package://assets/meshes/l_larm_joint.dae"/>
      </geometry>
    </collision>
    <inertial>
      <mass value="0.0124"/>
      <origin xyz="-0.008596 0.015762 0.002150"/>
      <inertia ixx="70.485497e-10" ixy="1.04342163e-08" ixz="-0.000005e-10" iyy="188.648819e-10" iyz="-3.8465e-10" izz="236.494141e-10"/>
    </inertial>
  </link>
  <link name="l_larm">
    <visual>
      <origin rpy="0 0 0" xyz="0 0 0"/>
      <geometry>
        <mesh filename="package://assets/meshes/l_larm.dae"/>
      </geometry>
    </visual>
    <collision>
      <origin rpy="0 0 0" xyz="0 0 0"/>
      <geometry>
        <mesh filename="package://assets/meshes/l_larm.dae"/>
      </geometry>
    </collision>
    <inertial>
      <mass value="0.0812"/>
      <origin xyz="-0.008596 0.027572 0.000420"/>
      <inertia ixx="342.361237e-10" ixy="-3.6e-15" ixz="0.000012e-10" iyy="141.587677e-10" iyz="3.82193e-11" izz="414.116486e-10"/>
    </inertial>
  </link>
  <link name="l_hand">
    <visual>
      <origin rpy="0 0 0" xyz="0 0 0"/>
      <geometry>
        <mesh filename="package://assets/meshes/l_hand.dae"/>
      </geometry>
    </visual>
    <collision>
      <origin rpy="0 0 0" xyz="0 0 0"/>
      <geometry>
        <mesh filename="package://assets/meshes/l_hand.dae"/>
      </geometry>
    </collision>
    <inertial>
      <mass value="0.0046"/>
      <origin xyz="0.001817 0.018911 0.002717"/>
      <inertia ixx="8.193970e-10" ixy="-1.78483e-11" ixz="0.194812e-10" iyy="3.111708e-10" iyz="-2.003531e-10" izz="9.081884e-10"/>
    </inertial>
  </link>
  <joint name="l_shy_joint" type="revolute">
    <origin rpy="0 0 0" xyz="0 0.0359 0.113043"/>
    <axis xyz="0 1 0"/>
    <limit effort="0" lower="-1.88495559215" upper="2.23838476568" velocity="428.6"/>
    <parent link="base_link"/>
    <child link="l_uarm_joint"/>
  </joint>
  <joint name="l_shx_joint" type="revolute">
    <origin rpy="0 0 0" xyz="0 0.0189 0"/>
    <axis xyz="1 0 0"/>
    <limit effort="0" lower="-1.59808891297" upper="0.0530143760293" velocity="428.6"/>
    <parent link="l_uarm_joint"/>
    <child link="l_uarm"/>
  </joint>
  <joint name="l_ely_joint" type="revolute">
    <origin rpy="0 0 0" xyz="0.0088013 0.060007 0"/>
    <axis xyz="0 1 0"/>
    <limit effort="0" lower="-2.24604239778" upper="2.34441351774" velocity="428.6"/>
    <parent link="l_uarm"/>
    <child link="l_larm_joint"/>
  </joint>
  <joint name="l_elx_joint" type="revolute">
    <origin rpy="0 0 0" xyz="0 0.024054 0"/>
    <axis xyz="1 0 0"/>
    <limit effort="0" lower="-2.07639639448" upper="0.235619449019" velocity="428.6"/>
    <parent link="l_larm_joint"/>
    <child link="l_larm"/>
  </joint>
  <joint name="l_wry_joint" type="revolute">
    <origin rpy="0 0 0" xyz="0 0.061348 0"/>
    <axis xyz="0 1 0"/>
    <limit effort="0" lower="-2.35619449019" upper="2.06167017892" velocity="428.6"/>
    <parent link="l_larm"/>
    <child link="l_hand"/>
  </joint>
  <gazebo reference="l_uarm_joint">
    <selfCollide>true</selfCollide>
  </gazebo>
  <gazebo reference="l_uarm">
    <selfCollide>true</selfCollide>
  </gazebo>
  <gazebo reference="l_larm_joint">
    <selfCollide>true</selfCollide>
  </gazebo>
  <gazebo reference="l_larm">
    <selfCollide>true</selfCollide>
  </gazebo>
  <gazebo reference="l_hand">
    <selfCollide>true</selfCollide>
  </gazebo>
  <link name="body">
    <visual>
      <geometry>
        <mesh filename="package://assets/meshes/body.dae"/>
      </geometry>
    </visual>
    <collision>
      <geometry>
        <mesh filename="package://assets/meshes/body.dae"/>
      </geometry>
    </collision>
    <inertial>
      <mass value="0.4426"/>
      <origin xyz="0.008509 0.000002 0.070698"/>
      <inertia ixx="2871.143311e-10" ixy="-0.001151e-10" ixz="237.094467e-10" iyy="2672.078857e-10" iyz="-0.003379e-10" izz="1188.332153e-10"/>
    </inertial>
  </link>
  <link name="neck_pitch">
    <visual>
      <geometry>
        <mesh filename="package://assets/meshes/neck_pitch.dae"/>
      </geometry>
    </visual>
    <collision>
      <geometry>
        <mesh filename="package://assets/meshes/neck_pitch.dae"/>
      </geometry>
    </collision>
    <inertial>
      <mass value="0.01"/>
      <origin xyz="-0.006449 0.000002 0.008964"/>
      <inertia ixx="6.489763e-10" ixy="-0.000003e-10" ixz="-0.024047e-10" iyy="2.296302e-10" iyz="-0.000005e-10" izz="6.197822e-10"/>
    </inertial>
  </link>
  <link name="head_yaw">
    <visual>
      <geometry>
        <mesh filename="package://assets/meshes/neck_yaw.dae"/>
      </geometry>
    </visual>
    <collision>
      <geometry>
        <mesh filename="package://assets/meshes/neck_yaw.dae"/>
      </geometry>
    </collision>
    <inertial>
      <mass value="0.01"/>
      <origin xyz="0.008100 0.000002 0.017871"/>
      <inertia ixx="12.636111e-10" ixy="-0.000001e-10" ixz="0.0" iyy="23.689224e-10" iyz="0.0" izz="17.372910e-10"/>
    </inertial>
  </link>
  <link name="head">
    <visual>
      <geometry>
        <mesh filename="package://assets/meshes/head.dae"/>
      </geometry>
    </visual>
    <collision>
      <geometry>
        <mesh filename="package://assets/meshes/head.dae"/>
      </geometry>
    </collision>
    <inertial>
      <mass value="0.1449"/>
      <origin xyz="0.014213 0.000001 0.011813"/>
      <inertia ixx="650.041687e-10" ixy="-0.000280e-10" ixz="49.702934e-10" iyy="598.413635e-10" iyz="-0.000379e-10" izz="588.398682e-10"/>
    </inertial>
  </link>
  <joint name="body_to_base_link" type="fixed">
    <origin rpy="0 0 0" xyz="0 0 0"/>
    <parent link="base_link"/>
    <child link="body"/>
  </joint>
  <joint name="head_ny_joint" type="revolute">
    <origin rpy="0 0 0" xyz="0.0038738 0 0.132809"/>
    <axis xyz="0 1 0"/>
    <limit effort="0" lower="-0.176714586764" upper="0.412334035784" velocity="428.6"/>
    <parent link="body"/>
    <child link="neck_pitch"/>
  </joint>
  <joint name="head_nz_joint" type="revolute">
    <origin rpy="0 0 0" xyz="-0.0103485 0 0.011103"/>
    <axis xyz="0 0 1"/>
    <limit effort="0" lower="-0.824668071567" upper="0.824668071567" velocity="428.6"/>
    <parent link="neck_pitch"/>
    <child link="head_yaw"/>
  </joint>
  <joint name="head_nx_joint" type="revolute">
    <origin rpy="0 0 0" xyz="0 0 0.0129"/>
    <axis xyz="1 0 0"/>
    <limit effort="0" lower="-0.382881604656" upper="0.500691329166" velocity="428.6"/>
    <parent link="head_yaw"/>
    <child link="head"/>
  </joint>
  <gazebo reference="body">
    <selfCollide>true</selfCollide>
  </gazebo>
  <gazebo reference="neck_pitch">
    <selfCollide>false</selfCollide>
  </gazebo>
  <gazebo reference="neck_yaw">
    <selfCollide>false</selfCollide>
  </gazebo>
  <gazebo reference="head">
    <selfCollide>true</selfCollide>
  </gazebo>
</robot>
